<?xml version="1.0" ?>
<!-- =================================================================================== -->
<!-- |    This document was autogenerated by xacro from urdf/rover.urdf.xacro          | -->
<!-- |    EDITING THIS FILE BY HAND IS NOT RECOMMENDED                                 | -->
<!-- =================================================================================== -->
<robot name="mock_rover">
  <link name="base_link">
    <inertial>
      <origin xyz="0 0 0"/>
      <mass value="30"/>
      <inertia ixx="2.0" ixy="0" ixz="0" iyy="2.0" iyz="0" izz="2.0"/>
    </inertial>
    <visual>
      <origin xyz="0 0 0.15"/>
      <geometry>
        <box size="0.8 0.6 0.3"/>
      </geometry>
    </visual>
    <collision>
      <origin xyz="0 0 0.15"/>
      <geometry>
        <box size="0.8 0.6 0.3"/>
      </geometry>
    </collision>
  </link>
  <link name="front_left_wheel">
    <visual>
      <origin rpy="1.5708 0 0"/>
      <geometry>
        <cylinder length="0.08" radius="0.12"/>
      </geometry>
    </visual>
    <collision>
      <origin rpy="1.5708 0 0"/>
      <geometry>
        <cylinder length="0.08" radius="0.12"/>
      </geometry>
    </collision>
    <inertial>
      <mass value="1"/>
      <origin xyz="0 0 0"/>
      <inertia ixx="0.01" ixy="0" ixz="0" iyy="0.01" iyz="0" izz="0.01"/>
    </inertial>
  </link>
  <joint name="front_left_joint" type="continuous">
    <parent link="base_link"/>
    <child link="front_left_wheel"/>
    <origin xyz="0.3 0.25 0.12"/>
    <axis xyz="0 1 0"/>
  </joint>
  <link name="front_right_wheel">
    <visual>
      <origin rpy="1.5708 0 0"/>
      <geometry>
        <cylinder length="0.08" radius="0.12"/>
      </geometry>
    </visual>
    <collision>
      <origin rpy="1.5708 0 0"/>
      <geometry>
        <cylinder length="0.08" radius="0.12"/>
      </geometry>
    </collision>
    <inertial>
      <mass value="1"/>
      <origin xyz="0 0 0"/>
      <inertia ixx="0.01" ixy="0" ixz="0" iyy="0.01" iyz="0" izz="0.01"/>
    </inertial>
  </link>
  <joint name="front_right_joint" type="continuous">
    <parent link="base_link"/>
    <child link="front_right_wheel"/>
    <origin xyz="0.3 -0.25 0.12"/>
    <axis xyz="0 1 0"/>
  </joint>
  <link name="rear_left_wheel">
    <visual>
      <origin rpy="1.5708 0 0"/>
      <geometry>
        <cylinder length="0.08" radius="0.12"/>
      </geometry>
    </visual>
    <collision>
      <origin rpy="1.5708 0 0"/>
      <geometry>
        <cylinder length="0.08" radius="0.12"/>
      </geometry>
    </collision>
    <inertial>
      <mass value="1"/>
      <origin xyz="0 0 0"/>
      <inertia ixx="0.01" ixy="0" ixz="0" iyy="0.01" iyz="0" izz="0.01"/>
    </inertial>
  </link>
  <joint name="rear_left_joint" type="continuous">
    <parent link="base_link"/>
    <child link="rear_left_wheel"/>
    <origin xyz="-0.3 0.25 0.12"/>
    <axis xyz="0 1 0"/>
  </joint>
  <link name="rear_right_wheel">
    <visual>
      <origin rpy="1.5708 0 0"/>
      <geometry>
        <cylinder length="0.08" radius="0.12"/>
      </geometry>
    </visual>
    <collision>
      <origin rpy="1.5708 0 0"/>
      <geometry>
        <cylinder length="0.08" radius="0.12"/>
      </geometry>
    </collision>
    <inertial>
      <mass value="1"/>
      <origin xyz="0 0 0"/>
      <inertia ixx="0.01" ixy="0" ixz="0" iyy="0.01" iyz="0" izz="0.01"/>
    </inertial>
  </link>
  <joint name="rear_right_joint" type="continuous">
    <parent link="base_link"/>
    <child link="rear_right_wheel"/>
    <origin xyz="-0.3 -0.25 0.12"/>
    <axis xyz="0 1 0"/>
  </joint>
  <link name="depth_camera_link">
    <inertial>
      <mass value="0.1"/>
      <origin xyz="0 0 0"/>
      <inertia ixx="0.0001" ixy="0.0" ixz="0.0" iyy="0.0001" iyz="0.0" izz="0.0001"/>
    </inertial>
    <visual>
      <geometry>
        <box size="0.08 0.08 0.05"/>
      </geometry>
    </visual>
    <collision>
      <geometry>
        <box size="0.08 0.08 0.05"/>
      </geometry>
    </collision>
  </link>
  <joint name="depth_camera_joint" type="fixed">
    <parent link="base_link"/>
    <child link="depth_camera_link"/>
    <origin xyz="0.25 0 0.35"/>
  </joint>
  <gazebo reference="depth_camera_link">
    <sensor name="depth_camera" type="depth_camera">
      <always_on>true</always_on>
      <visualize>true</visualize>
      <update_rate>30</update_rate>
      <camera>
        <horizontal_fov>1.9</horizontal_fov>
        <image>
          <width>640</width>
          <height>480</height>
        </image>
        <clip>
          <near>0.1</near>
          <far>20.0</far>
        </clip>
      </camera>
    </sensor>
  </gazebo>
  <gazebo>
    <plugin filename="gz-sim-diff-drive-system" name="gz::sim::systems::DiffDrive">
      <left_joint>front_left_joint</left_joint>
      <left_joint>rear_left_joint</left_joint>
      <right_joint>front_right_joint</right_joint>
      <right_joint>rear_right_joint</right_joint>
      <wheel_separation>0.5</wheel_separation>
      <wheel_radius>0.12</wheel_radius>
      <topic>/cmd_vel</topic>
    </plugin>
  </gazebo>
</robot>
